Workbook
Name NativeTimeline_published_date: #N/A
Name Slicer_county: #N/A
Name Slicer_murder_scene: #N/A
Name Slicer_Region: #N/A
Name Slicer_status_on_article_date: #N/A
Name Slicer_suspect_relationship: #N/A
Name Slicer_type_of_femicide: #N/A

Sheet Dashboard

Sheet Original data
A1: Author Name | B1: medium | C1: published_date | D1: type_of_murder | E1: name_of_victim | F1: age | G1: date_of_murder | H1: name_of_suspect | I1: suspect relationship | J1: type_of_femicide | K1: murder_scene | L1: mode_of_killing | M1: circumstance | N1: status_on_article_date | O1: court_date_(first_appearance) | P1: verdict_date | Q1: verdict | R1: years_of_sentence | S1: days_to_verdict | T1: area | U1: county | V1: Region
A2: Carolyne Kubwa | B2: The Star | C2: 43649 | D2: Femicide | E2: Damaris kibe | H2: Isaac Kirui | I2: Husband | J2: Intimate | K2: home | L2: other | M2: Not Provided | N2: Not Provided | P2: 43649 | Q2: guilty | S2: 2068 | T2: Not Provided | U2: Not Provided | V2: =_xlfn.XLOOKUP(U2, Mapping!$A$2:$A$48, Mapping!$B$2:$B$48, "Unknown County") -> Unknown County
A3: Citizen Reporter | B3: Citizen Digital | C3: 44746 | D3: Femicide | E3: Not Provided | F3: 24 | H3: Joseph Kiplimo | I3: Husband | J3: Intimate | K3: home | L3: hacked | M3: Argument | N3: under investigation | Q3: Not Provided | T3: Not Provided | U3: Not Provided | V3: =_xlfn.XLOOKUP(U3, Mapping!$A$2:$A$48, Mapping!$B$2:$B$48, "Unknown County") -> Unknown County
A4: Anne Atieno | B4: Not Provided | C4: 44698 | D4: Femicide | E4: Joyce Aluoch | H4: Charles Odhiambo | I4: Husband | J4: Not Provided | K4: Not Provided | L4: blunt force | M4: Not Provided | N4: Not Provided | Q4: Guilty | T4: Not Provided | U4: Not Provided | V4: =_xlfn.XLOOKUP(U4, Mapping!$A$2:$A$48, Mapping!$B$2:$B$48, "Unknown County") -> Unknown County
A5: Annette Wambulwa | B5: The Star | C5: 42607 | D5: Femicide | E5: Rose Wekesa | H5: Storum Miheso | I5: Husband | J5: intimate | K5: Not Provided | L5: Not Provided | M5: Not Provided | N5: Not Provided | Q5: Not Provided | T5: Not Provided | U5: Not Provided | V5: =_xlfn.XLOOKUP(U5, Mapping!$A$2:$A$48, Mapping!$B$2:$B$48, "Unknown County") -> Unknown County
A6: Not Provided | B6: Standard Media | D6: Femicide | E6: Naomi Tuitoek | F6: 27 | H6: Not Provided | I6: Husband | J6: Not Provided | K6: Not Provided | L6: Not Provided | M6: Not Provided | N6: Not Provided | Q6: Not Provided | T6: Baringo County | U6: Baringo | V6: =_xlfn.XLOOKUP(U6, Mapping!$A$2:$A$48, Mapping!$B$2:$B$48, "Unknown County") -> Rift Valley
A7: Carole Maina | B7: The Star | C7: 42691 | D7: Femicide | E7: Diana Chemutai (Chelele) | H7: Eric Musila | I7: Ex-Husband | J7: Intimate | K7: home | L7: Not Provided | M7: Argument | N7: Not Provided | O7: 42720 | P7: 43588 | Q7: Not Guilty | R7: 0 | S7: 1212 | T7: Kapkwen | U7: Bomet | V7: =_xlfn.XLOOKUP(U7, Mapping!$A$2:$A$48, Mapping!$B$2:$B$48, "Unknown County") -> Rift Valley
A8: Gilbert Kimutai | B8: Standard Digital | C8: 43353 | D8: Femicide | E8: Not Provided | F8: 24 | H8: Not Provided | I8: Ex-Boyfriend | J8: Intimate | K8: home | L8: stabbed | M8: jealousy | N8: under investigation | Q8: Not Provided | T8: Chemaner location | U8: Bomet | V8: =_xlfn.XLOOKUP(U8, Mapping!$A$2:$A$48, Mapping!$B$2:$B$48, "Unknown County") -> Rift Valley
A9: Vitalis Kimutai | B9: Daily Nation | C9: 43597 | D9: Femicide | E9: Caroline Kirui | F9: 20 | G9: 43596 | H9: Gilbert Kipngetich Kirui | I9: Husband | J9: Intimate | K9: home | L9: hacked | M9: Argument | N9: under investigation | Q9: Not Provided | T9: Konoin | U9: Bomet | V9: =_xlfn.XLOOKUP(U9, Mapping!$A$2:$A$48, Mapping!$B$2:$B$48, "Unknown County") -> Rift Valley
A10: Stella Cherono | B10: Daily Nation | D10: Femicide | E10: Emmy Chepkoech Mitey | F10: 45 | H10: Robert Tonui | I10: Boyfriend | J10: Intimate | K10: Home | L10: burned | M10: divorce/separation | N10: Not Provided | Q10: Not Provided | T10: Seanin | U10: Bomet | V10: =_xlfn.XLOOKUP(U10, Mapping!$A$2:$A$48, Mapping!$B$2:$B$48, "Unknown County") -> Rift Valley
A11: Paul Ruto | B11: Citizen Digital | C11: 44471 | D11: Femicide | E11: Not Provided | F11: 25 | H11: Nickson Sang | I11: Husband | J11: Intimate | K11: home | L11: stabbed | M11: Argument | N11: under investigation | Q11: Not Provided | T11: Kipreres | U11: Bomet | V11: =_xlfn.XLOOKUP(U11, Mapping!$A$2:$A$48, Mapping!$B$2:$B$48, "Unknown County") -> Rift Valley
A12: Not Provided | B12: Not Provided | C12: 44651 | D12: Femicide | E12: Faith Chepkoech | F12: 25 | H12: Gilbert Langat | I12: Husband | J12: Not Provided | K12: Home | L12: stabbed | M12: Not Provided | N12: Not Provided | Q12: Not Provided | T12: Mauche estate within Bomet Township | U12: Bomet | V12: =_xlfn.XLOOKUP(U12, Mapping!$A$2:$A$48, Mapping!$B$2:$B$48, "Unknown County") -> Rift Valley
A13: Kna | B13: The Star | C13: 44936 | D13: Femicide | E13: Not Provided | F13: 38 | H13: Not Provided | I13: Stranger | J13: Non-intimate | K13: Public Space | L13: Strangled | M13: Not Provided | N13: under investigation | Q13: Not Provided | T13: Tembwo trading centre | U13: Bomet | V13: =_xlfn.XLOOKUP(U13, Mapping!$A$2:$A$48, Mapping!$B$2:$B$48, "Unknown County") -> Rift Valley
A14: Paul Ruto | B14: Citizen Digital | C14: 45260 | D14: Femicide | E14: Not Provided | H14: Niphael Kiprotich Ngetich | I14: Husband | J14: INtimate | K14: Home | L14: blunt force | M14: Domestic wrangle | N14: under investigation | Q14: Not Provided | T14: Korara area | U14: Bomet | V14: =_xlfn.XLOOKUP(U14, Mapping!$A$2:$A$48, Mapping!$B$2:$B$48, "Unknown County") -> Rift Valley
A15: Brian Ojamaa | B15: The Star | C15: 42845 | D15: Femicide | E15: Abigail Wafula | F15: 16 | H15: Kizito Wafula | I15: Family Member | J15: Non-intimate | K15: home | L15: blunt force | M15: Others | N15: Not Provided | Q15: Not Provided | T15: Misemwa village | U15: Bungoma | V15: =_xlfn.XLOOKUP(U15, Mapping!$A$2:$A$48, Mapping!$B$2:$B$48, "Unknown County") -> Western
A16: Brian Ojamaa | B16: The Star | C16: 42838 | D16: Femicide | E16: Feophe Ekas | F16: 28 | H16: Alln Osiome | I16: Husband | J16: Intimate | K16: home | L16: stabbed | M16: Argument | N16: Not Provided | Q16: Not Provided | T16: Sirisia constituency | U16: Bungoma | V16: =_xlfn.XLOOKUP(U16, Mapping!$A$2:$A$48, Mapping!$B$2:$B$48, "Unknown County") -> Western
A17: Not Provided | B17: The Star | C17: 43128 | D17: Femicide | E17: Sara Nyanyama | F17: 37 | H17: Ben Wafula | I17: Husband | J17: Intimate | K17: home | L17: blunt force | M17: Argument | N17: under investigation | Q17: Not Provided | T17: Not Provided | U17: Bungoma | V17: =_xlfn.XLOOKUP(U17, Mapping!$A$2:$A$48, Mapping!$B$2:$B$48, "Unknown County") -> Western
A18: Raphael Wanjala | B18: Standard Digital | C18: 43154 | D18: Femicide | E18: Mildred Wanyonyi | H18: Simon Wamalwa | I18: Boyfriend | J18: Intimate | K18: school | L18: stabbed | M18: jealousy | N18: under investigation | Q18: Not Provided | T18: Sang'alo Institute of Science and Technology | U18: Bungoma | V18: =_xlfn.XLOOKUP(U18, Mapping!$A$2:$A$48, Mapping!$B$2:$B$48, "Unknown County") -> Western
A19: Brian Ojamaa | B19: The Star | C19: 43295 | D19: Femicide | E19: Not Provided | F19: 33 | H19: Jared Nyongesa | I19: Husband | J19: Intimate | K19: home | L19: hacked | M19: Argument | N19: under investigation | Q19: Not Provided | T19: Kanduyi vilage | U19: Bungoma | V19: =_xlfn.XLOOKUP(U19, Mapping!$A$2:$A$48, Mapping!$B$2:$B$48, "Unknown County") -> Western
A20: Brian Ojamaa | B20: The Star | C20: 43295 | D20: Femicide | E20: Not Provided | F20: 33 | H20: Jared Nyongesa | I20: Husband | J20: Intimate | K20: home | L20: Blunt force | M20: Argument | N20: under investigation | Q20: Not Provided | T20: Kanduyi | U20: Bungoma | V20: =_xlfn.XLOOKUP(U20, Mapping!$A$2:$A$48, Mapping!$B$2:$B$48, "Unknown County") -> Western
A21: Brian Ojamaa | B21: The Star | C21: 43387 | D21: Femicide | E21: Irene Sifuna | H21: Not Provided | I21: Stranger | J21: Not Provided | K21: home | L21: stabbed | M21: Not Provided | N21: under investigation | Q21: Not Provided | T21: Not Provided | U21: Bungoma | V21: =_xlfn.XLOOKUP(U21, Mapping!$A$2:$A$48, Mapping!$B$2:$B$48, "Unknown County") -> Western
A22: Raphael Wanjala | B22: Standard Digital | C22: 43403 | D22: Femicide | E22: Sarah Chebet | H22: Not Provided | I22: Stranger | J22: Not Provided | K22: Public Space | L22: hacked | M22: Not Provided | N22: under investigation | Q22: Not Provided | T22: Cheptais sub-county | U22: Bungoma | V22: =_xlfn.XLOOKUP(U22, Mapping!$A$2:$A$48, Mapping!$B$2:$B$48, "Unknown County") -> Western
A23: Not Provided | B23: Citizen TV | D23: Femicide | E23: Helen Namalwa | F23: 42 | H23: Not Provided | I23: Boyfriend | J23: Not Provided | K23: Not Provided | L23: Not Provided | M23: Not Provided | N23: Not Provided | Q23: Not Provided | T23: Bungoma County | U23: Bungoma | V23: =_xlfn.XLOOKUP(U23, Mapping!$A$2:$A$48, Mapping!$B$2:$B$48, "Unknown County") -> Western
A24: Tony Wafula | B24: The Star | C24: 45139 | D24: Femicide | E24: Margaret Kamanga | H24: Gerald Kamanga | I24: Husband | J24: INtimate | K24: Home | L24: blunt force | M24: Not Provided | N24: under investigation | Q24: Not Provided | T24: Wamunyiri village | U24: Bungoma | V24: =_xlfn.XLOOKUP(U24, Mapping!$A$2:$A$48, Mapping!$B$2:$B$48, "Unknown County") -> Western
A25: Carolyne Kubwa | B25: The Star | C25: 43934 | D25: Femicide | E25: Eunice Ojuro | H25: Julius Nyekenye Serikali | I25: Husband | J25: Intimate | K25: home | L25: blunt force | M25: Argument | N25: Not Provided | P25: 43934 | Q25: guilty | S25: 944 | T25: Esikulu village | U25: Busia | V25: =_xlfn.XLOOKUP(U25, Mapping!$A$2:$A$48, Mapping!$B$2:$B$48, "Unknown County") -> Western
A26: Annette Wambulwa | B26: The Star | C26: 44119 | D26: Femicide | E26: Eunice Akisa | H26: Antony Paste Obwalo | I26: Husband | J26: Intimate | K26: home | L26: blunt force | M26: Argument | N26: Not Provided | Q26: guilty | S26: 308 | T26: Okwata village | U26: Busia | V26: =_xlfn.XLOOKUP(U26, Mapping!$A$2:$A$48, Mapping!$B$2:$B$48, "Unknown County") -> Western
A27: Robert Amalemba | B27: Standard Digital | C27: 44514 | D27: Femicide | E27: Caroline Nabwire | H27: John Wandera | I27: Boyfriend | J27: Intimate | K27: home | L27: blunt force | M27: Not Provided | N27: Ongoing hearing | Q27: Not Provided | T27: Nasemwa village | U27: Busia | V27: =_xlfn.XLOOKUP(U27, Mapping!$A$2:$A$48, Mapping!$B$2:$B$48, "Unknown County") -> Western
A28: Nathan Ochunge | B28: Standard digital | C28: 44322 | D28: Femicide | E28: Zipporah Nkirote | G28: 44322 | H28: Not Provided | I28: Husband | J28: Not Provided | K28: Home | L28: stabbed | M28: Not Provided | N28: Not Provided | Q28: Not Provided | T28: Matayos Sub-County | U28: Busia | V28: =_xlfn.XLOOKUP(U28, Mapping!$A$2:$A$48, Mapping!$B$2:$B$48, "Unknown County") -> Western
A29: Callistus Muga | B29: Citizen Digital | C29: 44371 | D29: Femicide | E29: Not Provided | H29: Not Provided | I29: Husband | J29: Intimate | K29: home | L29: shot | M29: Argument | N29: both are dead | Q29: Not Provided | T29: Funyula | U29: Busia | V29: =_xlfn.XLOOKUP(U29, Mapping!$A$2:$A$48, Mapping!$B$2:$B$48, "Unknown County") -> Western
A30: Hilary Kimuyu | B30: Nairobi News | C30: 45259 | D30: Femicide | E30: Mercy Chebet | H30: Constable Maxwell Maina | I30: Husband | J30: INtimate | K30: Home | L30: shot | M30: Not Provided | N30: under investigation | Q30: Not Provided | T30: Railways Police Lines | U30: Uasin Gishu | V30: =_xlfn.XLOOKUP(U30, Mapping!$A$2:$A$48, Mapping!$B$2:$B$48, "Unknown County") -> Rift Valley
A31: Stephen Rutto | B31: The Star | C31: 43262 | D31: Femicide | E31: Peris Jemaiyo | F31: 26 | H31: Richard Ruto | I31: Husband | J31: Intimate | K31: home | L31: stabbed | M31: Argument | N31: under investigation | Q31: Not Provided | T31: Marakwet East | U31: Elgeyo Marakwet | V31: =_xlfn.XLOOKUP(U31, Mapping!$A$2:$A$48, Mapping!$B$2:$B$48, "Unknown County") -> Rift Valley
A32: Fred Kibor | B32: Standard Digital | C32: 43276 | D32: Femicide | E32: Marion Cheruiyot | F32: 22 | H32: Josphat Cheruiyot | I32: Husband | J32: Intimate | K32: home | L32: hacked | M32: Argument | N32: under investigation | Q32: Not Provided | T32: Boe Vilage | U32: Elgeyo Marakwet | V32: =_xlfn.XLOOKUP(U32, Mapping!$A$2:$A$48, Mapping!$B$2:$B$48, "Unknown County") -> Rift Valley
A33: Mireri Junior | B33: Standard Digital | C33: 44337 | D33: Femicide | E33: Not Provided | F33: 23 | G33: 44336 | H33: Not Provided | I33: Husband | J33: Intimate | K33: home | L33: hacked | M33: Argument | N33: under investigation | Q33: Not Provided | T33: Tambul village | U33: Elgeyo Marakwet | V33: =_xlfn.XLOOKUP(U33, Mapping!$A$2:$A$48, Mapping!$B$2:$B$48, "Unknown County") -> Rift Valley
A34: Daily Nation | B34: The East African | C34: 44487 | D34: Femicide | E34: Agnes Tirop | F34: 25 | H34: Ibrahim Rotich | I34: Husband | J34: Intimate | K34: home | L34: stabbed | M34: Not Provided | N34: Ongoing hearing | O34: 44487 | Q34: Not Provided | T34: Iten town | U34: Elgeyo Marakwet | V34: =_xlfn.XLOOKUP(U34, Mapping!$A$2:$A$48, Mapping!$B$2:$B$48, "Unknown County") -> Rift Valley
A35: Stephen Rutto | B35: Standard Digital | C35: 44670 | D35: Femicide | E35: Damaris Muthee | H35: Eskanda Hailemariam | I35: Boyfriend | J35: Intimate | K35: home | L35: strangled | M35: Not Provided | N35: under investigation | Q35: Not Provided | T35: Iten town | U35: Elgeyo Marakwet | V35: =_xlfn.XLOOKUP(U35, Mapping!$A$2:$A$48, Mapping!$B$2:$B$48, "Unknown County") -> Rift Valley
A36: Bashir Mbuthia | B36: Not Provided | C36: 44688 | D36: Femicide | E36: Monica Jepto | F36: 38 | H36: Khadiri Khamisi | I36: Husband | J36: Not Provided | K36: Home | L36: stabbed | M36: Not Provided | N36: Not Provided | Q36: Not Provided | T36: Iten | U36: Elgeyo Marakwet | V36: =_xlfn.XLOOKUP(U36, Mapping!$A$2:$A$48, Mapping!$B$2:$B$48, "Unknown County") -> Rift Valley
A37: Anthony Ndwiga | B37: citizen digital | C37: 42827 | D37: Femicide | E37: Not Provided | F37: 80 | H37: Not Provided | I37: Stranger | J37: non-intimate | K37: home | L37: sexual assault | M37: Not Provided | N37: Under Investigation | Q37: Not Provided | T37: Kigumo Village | U37: Embu | V37: =_xlfn.XLOOKUP(U37, Mapping!$A$2:$A$48, Mapping!$B$2:$B$48, "Unknown County") -> Eastern
A38: Reuben Githinji | B38: The Star | C38: 43231 | D38: Femicide | E38: Pauline Kagendo | H38: Edwin Mwenda | I38: Ex-Boyfriend | J38: Intimate | K38: home | L38: Not Provided | M38: Argument | N38: Not Provided | Q38: Not Provided | T38: Njarange village | U38: Embu | V38: =_xlfn.XLOOKUP(U38, Mapping!$A$2:$A$48, Mapping!$B$2:$B$48, "Unknown County") -> Eastern
A39: Charles Wanyoro | B39: Daily Nation | C39: 43264 | D39: Femicide | E39: Naomi Warunji | F39: 93 | H39: Not Provided | I39: Stranger | J39: Not Provided | K39: home | L39: stabbed | M39: Organized crime | N39: under investigation | Q39: Not Provided | T39: Gitumbi vilage | U39: Embu | V39: =_xlfn.XLOOKUP(U39, Mapping!$A$2:$A$48, Mapping!$B$2:$B$48, "Unknown County") -> Eastern
A40: George Munene | B40: Daily Nation | C40: 43896 | D40: Femicide | E40: Not Provided | F40: 44 | H40: Not Provided | I40: Friend | J40: Non-intimate | K40: home | L40: strangled | M40: Not Provided | N40: under investigation | Q40: Not Provided | T40: Njigo village | U40: Embu | V40: =_xlfn.XLOOKUP(U40, Mapping!$A$2:$A$48, Mapping!$B$2:$B$48, "Unknown County") -> Eastern
...

Sheet victims by age & type of femici
A3: Count of name_of_victim | B3: Column Labels
A4: Row Labels | B4: Intimate | C4: Non-intimate | D4: Grand Total
A5: 6-16 | B5: 1 | C5: 8 | D5: 9
A6: 16-26 | B6: 69 | C6: 13 | D6: 82
A7: 26-36 | B7: 75 | C7: 6 | D7: 81
A8: 36-46 | B8: 35 | C8: 4 | D8: 39
A9: 46-56 | B9: 9 | D9: 9
A10: 56-66 | B10: 2 | C10: 3 | D10: 5
A11: 66-76 | B11: 1 | C11: 5 | D11: 6
A12: 76-86 | C12: 6 | D12: 6
A13: 86-96 | C13: 2 | D13: 2
A14: Grand Total | B14: 192 | C14: 47 | D14: 239

Sheet number of victims by scene
A3: Row Labels | B3: Count of type_of_murder
A4: home | B4: 298
A5: Not Provided | B5: 6
A6: Other | B6: 10
A7: Public Space | B7: 79
A8: school | B8: 3
A9: Workplace | B9: 2
A10: Grand Total | B10: 398

Sheet victims by circumstances
A3: Row Labels | B3: Count of name_of_victim
A4: Accused of infidelity | B4: 1
A5: altercation | B5: 1
A6: angered he could not marry her because they were relatives | B6: 1
A7: Argument | B7: 156
A8: argument during a drinking spree | B8: 1
A9: breakup | B9: 13
A10: deceived her by claiming to have found her lost phone | B10: 1
A11: denied conjugal rights | B11: 1
A12: denied him access to the Sh11,500 monthly support from Red Cross Society | B12: 1
A13: Denied sex | B13: 2
A14: Denied to marry her | B14: 1
A15: Denying him conjugal rights | B15: 1
... A45: Grand Total | B45: 274

Sheet victims by type_relationship
A3: Row Labels | B3: Count of type_of_murder
A4: Boyfriend | B4: 105
A5: Ex-Boyfriend | B5: 14
A6: Ex-Husband | B6: 16
A7: Family Member | B7: 13
A8: Friend | B8: 22
A9: Husband | B9: 191
A10: Not Provided | B10: 2
A11: Stranger | B11: 35
A12: Grand Total | B12: 398

Sheet femicide victims by region
A4: Row Labels | B4: Count of type_of_murder
A5: Central | B5: 95
A6: Coast | B6: 23
A7: Eastern | B7: 58
A8: Nairobi | B8: 75
A9: North Eastern | B9: 3
A10: Nyanza | B10: 61
A11: Rift Valley | B11: 152
A12: Western | B12: 35
A13: Grand Total | B13: 502

Sheet verdict
A3: Row Labels | B3: Count of Author Name
A4: 15 years | B4: 1
A5: guilty | B5: 32
A6: Not Guilty | B6: 3
A7: Grand Total | B7: 36

Sheet total number of cases by publis
A3: Row Labels | B3: Count of type_of_murder
A4: <01/01/2016 | B4: 38
A5: 2016 | B5: 23
A6: 2017 | B6: 48
A7: 2018 | B7: 95
A8: 2019 | B8: 49
A9: 2020 | B9: 54
A10: 2021 | B10: 76
A11: 2022 | B11: 44
A12: 2023 | B12: 75
A13: Grand Total | B13: 502

Sheet victims by mode of killing 
A3: Row Labels | B3: Count of type_of_murder
A4: blunt force | B4: 76
A5: burned | B5: 13
A6: hacked | B6: 67
A7: Not Provided | B7: 65
A8: other | B8: 14
A9: sexual assault | B9: 18
A10: shot | B10: 31
A11: stabbed | B11: 154
A12: Strangled | B12: 64
A13: Grand Total | B13: 502

Sheet Mapping
A1: County | B1: Region
A2: Mombasa | B2: Coast
A3: Kwale | B3: Coast
A4: Kilifi | B4: Coast
A5: Tana River | B5: Coast
A6: Lamu | B6: Coast
A7: Taita Taveta | B7: Coast
A8: Garissa | B8: North Eastern
A9: Wajir | B9: North Eastern
A10: Mandera | B10: North Eastern
A11: Marsabit | B11: Eastern
A12: Isiolo | B12: Eastern
... A48: Nairobi | B48: Nairobi
